#!/usr/bin/env python3
"""
Error Scenarios and Failure Mode Testing
Comprehensive testing of error handling, failure recovery, and system resilience
Tests all possible error conditions and validates proper error handling
"""

import pytest
import asyncio
import json
import time
from pathlib import Path
from typing import Dict, List, Any, Optional
from unittest.mock import Mock, patch, AsyncMock, MagicMock
import requests
from requests.exceptions import ConnectionError, Timeout, HTTPError, RequestException
import socket
import dns.resolver
import sqlite3
from datetime import datetime

# Error simulation utilities
class NetworkErrorSimulator:
    """Utility to simulate various network error conditions"""
    
    @staticmethod
    def simulate_connection_error():
        """Simulate network connection failure"""
        raise ConnectionError("Network connection failed")
    
    @staticmethod
    def simulate_timeout_error():
        """Simulate request timeout"""
        raise Timeout("Request timed out after 30 seconds")
    
    @staticmethod
    def simulate_dns_error():
        """Simulate DNS resolution failure"""
        raise dns.resolver.NXDOMAIN("DNS resolution failed")
    
    @staticmethod
    def simulate_http_error(status_code=500):
        """Simulate HTTP error response"""
        response = Mock()
        response.status_code = status_code
        response.text = f"HTTP {status_code} Error"
        response.raise_for_status.side_effect = HTTPError(f"HTTP {status_code} Error")
        return response
    
    @staticmethod
    def simulate_database_error():
        """Simulate database connection error"""
        raise sqlite3.OperationalError("Database connection failed")

class TestDNSErrorHandling:
    """Test DNS system error handling and recovery"""
    
    @pytest.fixture
    def dns_manager(self):
        """Create DNS manager for error testing"""
        try:
            from dns.managers.dns_manager import DNSManager
            with patch.dict('os.environ', {'CLOUDFLARE_API_TOKEN': 'test_token'}):
                return DNSManager()
        except ImportError:
            pytest.skip("DNS manager not available")
    
    def test_invalid_api_token_handling(self, dns_manager):
        """Test handling of invalid API token"""
        from dns.managers.dns_manager import CloudflareAPIError
        
        error_response = {
            'success': False,
            'errors': [
                {'code': 10000, 'message': 'Authentication error'}
            ]
        }
        
        with patch.object(dns_manager, '_make_request', new_callable=AsyncMock) as mock_request:
            mock_request.return_value = error_response
            
            with pytest.raises(CloudflareAPIError, match="API Error"):
                asyncio.run(dns_manager.get_zones())
        
        # Verify error was logged appropriately
        assert hasattr(dns_manager, 'logger')
    
    def test_network_timeout_handling(self, dns_manager):
        """Test handling of network timeouts"""
        with patch.object(dns_manager.session, 'request') as mock_request:
            mock_request.side_effect = Timeout("Request timeout")
            
            with pytest.raises(Exception):  # Should raise appropriate error
                asyncio.run(dns_manager._make_request('GET', '/zones'))
    
    def test_rate_limiting_recovery(self, dns_manager):
        """Test automatic recovery from rate limiting"""
        with patch('asyncio.sleep') as mock_sleep:
            with patch.object(dns_manager.session, 'request') as mock_request:
                # First call returns 429 (rate limited)
                rate_limited_response = Mock()
                rate_limited_response.status_code = 429
                rate_limited_response.headers = {'Retry-After': '5'}
                
                # Second call succeeds
                success_response = Mock()
                success_response.status_code = 200
                success_response.json.return_value = {'success': True, 'result': []}
                success_response.raise_for_status.return_value = None
                
                mock_request.side_effect = [rate_limited_response, success_response]
                
                result = asyncio.run(dns_manager._make_request('GET', '/zones'))
                
                # Verify rate limiting was handled
                assert result['success'] is True
                mock_sleep.assert_called_with(5)  # Should sleep for retry-after duration
    
    def test_malformed_dns_record_handling(self, dns_manager):
        """Test handling of malformed DNS record data"""
        from dns.managers.dns_manager import DNSRecord
        
        with patch.object(dns_manager, 'get_zone_id', new_callable=AsyncMock) as mock_zone_id:
            with patch.object(dns_manager, '_make_request', new_callable=AsyncMock) as mock_request:
                mock_zone_id.return_value = 'zone_123'
                
                # Simulate API error for invalid record
                mock_request.return_value = {
                    'success': False,
                    'errors': [{'code': 1004, 'message': 'Invalid DNS record format'}]
                }
                
                invalid_record = DNSRecord(
                    type="A",
                    name="invalid..domain..com",  # Invalid domain format
                    content="not.an.ip.address",  # Invalid IP
                    ttl=-1  # Invalid TTL
                )
                
                with pytest.raises(Exception):
                    await dns_manager.create_dns_record("test.com", invalid_record)
    
    def test_zone_not_found_handling(self, dns_manager):
        """Test handling when DNS zone is not found"""
        dns_manager.zones_cache = {}  # Empty cache
        
        with patch.object(dns_manager, '_make_request', new_callable=AsyncMock) as mock_request:
            mock_request.return_value = {'success': True, 'result': []}  # No zones
            
            with pytest.raises(ValueError, match="Zone not found"):
                await dns_manager.get_zone_id("nonexistent.com")
    
    def test_partial_bulk_operation_failure(self, dns_manager):
        """Test handling of partial failures in bulk operations"""
        from dns.managers.dns_manager import DNSRecord
        
        records = [
            DNSRecord(type="A", name="valid.test.com", content="192.168.1.100"),
            DNSRecord(type="A", name="invalid.test.com", content="not_an_ip"),
            DNSRecord(type="A", name="another.test.com", content="192.168.1.101")
        ]
        
        call_count = 0
        async def mock_create_side_effect(domain, record):
            nonlocal call_count
            call_count += 1
            
            if record.name == "invalid.test.com":
                raise Exception("Invalid IP address")
            else:
                return {'id': f'record_{call_count}'}
        
        with patch.object(dns_manager, 'create_dns_record', side_effect=mock_create_side_effect):
            results = await dns_manager.bulk_create_records("test.com", records)
            
            # Should have 3 results: 2 successful, 1 error
            assert len(results) == 3
            
            successful_results = [r for r in results if 'id' in r]
            error_results = [r for r in results if 'error' in r]
            
            assert len(successful_results) == 2
            assert len(error_results) == 1

class TestMailcowErrorHandling:
    """Test Mailcow system error handling and recovery"""
    
    @pytest.fixture
    def mailcow_api(self):
        """Create Mailcow API for error testing"""
        try:
            from mailcow.core.api_client import MailcowAPI
            return MailcowAPI("mail.test.com", "test_key", verify_ssl=False)
        except ImportError:
            pytest.skip("Mailcow API not available")
    
    def test_ssl_verification_error_handling(self):
        """Test handling of SSL certificate errors"""
        from mailcow.core.api_client import MailcowAPI, MailcowAPIError
        
        # Create API with SSL verification enabled
        api = MailcowAPI("mail.test.com", "test_key", verify_ssl=True)
        
        with patch.object(api.session, 'request') as mock_request:
            mock_request.side_effect = requests.exceptions.SSLError("SSL certificate verification failed")
            
            with pytest.raises(MailcowAPIError, match="API request failed"):
                api.get('test/endpoint')
    
    def test_authentication_failure_handling(self, mailcow_api):
        """Test handling of authentication failures"""
        from mailcow.core.api_client import MailcowAPIError
        
        with patch.object(mailcow_api.session, 'request') as mock_request:
            auth_error_response = NetworkErrorSimulator.simulate_http_error(401)
            mock_request.return_value = auth_error_response
            
            with pytest.raises(MailcowAPIError, match="API request failed"):
                mailcow_api.get_domains()
    
    def test_mailcow_server_unavailable(self, mailcow_api):
        """Test handling when Mailcow server is unavailable"""
        with patch.object(mailcow_api.session, 'request') as mock_request:
            mock_request.side_effect = ConnectionError("Connection refused")
            
            # Test connection should return False
            result = mailcow_api.test_connection()
            assert result is False
    
    def test_domain_already_exists_error(self, mailcow_api):
        """Test handling of duplicate domain creation"""
        error_response = {
            'success': False,
            'msg': 'Domain already exists'
        }
        
        with patch.object(mailcow_api, '_request', return_value=error_response):
            result = mailcow_api.add_domain("existing.com")
            
            # Should return the error response without raising exception
            assert result['success'] is False
            assert 'already exists' in result['msg']
    
    def test_quota_exceeded_handling(self, mailcow_api):
        """Test handling of quota exceeded scenarios"""
        quota_error_response = {
            'success': False,
            'msg': 'Quota exceeded for domain'
        }
        
        with patch.object(mailcow_api, '_request', return_value=quota_error_response):
            result = mailcow_api.add_mailbox(
                "user@test.com", 
                "password", 
                quota=99999999  # Extremely high quota
            )
            
            assert result['success'] is False
            assert 'quota' in result['msg'].lower()
    
    def test_bulk_operation_timeout_recovery(self, mailcow_api):
        """Test recovery from timeouts during bulk operations"""
        mailboxes = [
            {"email": f"user{i}@test.com", "name": f"User {i}"} 
            for i in range(10)
        ]
        
        call_count = 0
        def mock_add_side_effect(**kwargs):
            nonlocal call_count
            call_count += 1
            
            # Simulate timeout on 5th call
            if call_count == 5:
                raise Timeout("Request timeout")
            else:
                return {"success": True}
        
        with patch.object(mailcow_api, 'add_mailbox', side_effect=mock_add_side_effect):
            results = mailcow_api.bulk_mailbox_create(mailboxes)
            
            # Should have 10 results, with one timeout error
            assert len(results) == 10
            
            successful = [r for r in results if r.get('success') is not False]
            failed = [r for r in results if r.get('success') is False]
            
            assert len(successful) == 9
            assert len(failed) == 1
            assert 'timeout' in str(failed[0]).lower()
    
    def test_json_decode_error_recovery(self, mailcow_api):
        """Test recovery from malformed JSON responses"""
        with patch.object(mailcow_api.session, 'request') as mock_request:
            malformed_response = Mock()
            malformed_response.status_code = 200
            malformed_response.content = b'malformed json response {'
            malformed_response.json.side_effect = json.JSONDecodeError("Invalid JSON", "doc", 0)
            malformed_response.raise_for_status.return_value = None
            mock_request.return_value = malformed_response
            
            from mailcow.core.api_client import MailcowAPIError
            
            with pytest.raises(MailcowAPIError, match="Failed to decode JSON response"):
                mailcow_api.get_domains()

class TestVPSErrorHandling:
    """Test VPS system error handling and recovery"""
    
    @pytest.fixture
    def vps_manager(self):
        """Create VPS manager for error testing"""
        try:
            from vps.core.vps_manager import VPSManager
            return VPSManager()
        except ImportError:
            pytest.skip("VPS manager not available")
    
    def test_insufficient_permissions_handling(self, vps_manager):
        """Test handling of insufficient system permissions"""
        with patch('subprocess.run') as mock_run:
            # Simulate permission denied error
            mock_run.side_effect = PermissionError("Permission denied")
            
            result = vps_manager.add_ip_alias("192.168.1.200", "eth0")
            
            # Should return False and log error appropriately
            assert result is False
    
    def test_network_interface_down_handling(self, vps_manager):
        """Test handling when network interface is down"""
        # Mock interface as down
        mock_stats = {
            'eth0': Mock(isup=False, mtu=1500)  # Interface is down
        }
        
        with patch('psutil.net_if_stats', return_value=mock_stats):
            interfaces = vps_manager.get_network_interfaces()
            
            # Should still return interface info but mark it as down
            assert 'eth0' in interfaces
            assert interfaces['eth0']['is_up'] is False
    
    def test_disk_space_monitoring_failure(self, vps_manager):
        """Test handling of disk space monitoring failures"""
        with patch('psutil.disk_usage') as mock_disk:
            mock_disk.side_effect = FileNotFoundError("Disk not found")
            
            status = vps_manager.get_vps_status()
            
            # Should handle the error gracefully
            assert 'disk' in status
            # Disk section might be empty or contain error info
    
    def test_system_resource_exhaustion(self, vps_manager):
        """Test behavior under resource exhaustion"""
        with patch('psutil.virtual_memory') as mock_memory:
            # Simulate very high memory usage
            mock_memory.return_value = Mock(
                total=8589934592,  # 8GB
                used=8419038699,   # 7.8GB used (95%)
                percent=95.0
            )
            
            status = vps_manager.get_vps_status()
            
            # Should report high memory usage without crashing
            assert status['system']['memory_percent'] == 95.0
            assert status['system']['memory_percent'] > 90  # High usage detected
    
    def test_service_monitoring_failure(self, vps_manager):
        """Test handling of service monitoring failures"""
        with patch('subprocess.run') as mock_run:
            # Simulate systemctl command failure
            mock_result = Mock()
            mock_result.stdout = ""
            mock_result.returncode = 1  # Command failed
            mock_run.return_value = mock_result
            
            status = vps_manager.get_vps_status()
            
            # Should handle service check failures gracefully
            assert 'services' in status
            
            # Services should be marked as down/unknown
            for service, is_running in status['services'].items():
                assert isinstance(is_running, bool)
    
    def test_ip_alias_conflict_handling(self, vps_manager):
        """Test handling of IP address conflicts"""
        with patch('subprocess.run') as mock_run:
            # Simulate IP already exists error
            error_result = Mock()
            error_result.returncode = 2
            error_result.stderr = "RTNETLINK answers: File exists"
            mock_run.return_value = error_result
            
            result = vps_manager.add_ip_alias("192.168.1.100", "eth0")  # IP already exists
            
            # Should return False and handle error appropriately
            assert result is False

class TestMonitoringErrorHandling:
    """Test monitoring system error handling and recovery"""
    
    @pytest.fixture
    def blacklist_monitor(self):
        """Create blacklist monitor for error testing"""
        try:
            from monitoring.monitors.blacklist_monitor import BlacklistMonitor
            return BlacklistMonitor()
        except ImportError:
            pytest.skip("Blacklist monitor not available")
    
    @pytest.fixture
    def warmup_campaigns(self):
        """Create warmup campaigns for error testing"""
        try:
            from monitoring.campaigns.warmup_campaigns import WarmupCampaigns
            return WarmupCampaigns()
        except ImportError:
            pytest.skip("Warmup campaigns not available")
    
    def test_dns_resolution_timeout_handling(self, blacklist_monitor):
        """Test handling of DNS resolution timeouts during blacklist checks"""
        with patch('dns.resolver.Resolver.resolve') as mock_resolve:
            mock_resolve.side_effect = dns.resolver.Timeout("DNS query timeout")
            
            # Should handle timeout gracefully
            result = asyncio.run(blacklist_monitor.check_ip_blacklists("192.168.1.100"))
            
            # Should return results (possibly empty) without crashing
            assert isinstance(result, list)
    
    def test_blacklist_provider_unavailable(self, blacklist_monitor):
        """Test handling when blacklist providers are unavailable"""
        with patch('dns.resolver.Resolver.resolve') as mock_resolve:
            mock_resolve.side_effect = dns.resolver.NXDOMAIN("Provider unreachable")
            
            result = asyncio.run(blacklist_monitor.check_ip_blacklists("192.168.1.100"))
            
            # Should handle provider unavailability
            assert isinstance(result, list)
            
            # Check that errors were logged appropriately
            for check in result:
                if hasattr(check, 'status'):
                    # Status should indicate the error condition
                    assert check.status in ['clear', 'error', 'timeout']
    
    def test_database_connection_failure(self, blacklist_monitor):
        """Test handling of database connection failures"""
        with patch('sqlite3.connect') as mock_connect:
            mock_connect.side_effect = sqlite3.OperationalError("Database locked")
            
            # Operations should handle database errors gracefully
            try:
                result = asyncio.run(blacklist_monitor.add_monitoring_target("192.168.1.100", "test.com"))
                # Should either return None or handle the error appropriately
                assert result is None or isinstance(result, int)
            except Exception as e:
                # If exception is raised, it should be a handled type
                assert isinstance(e, (sqlite3.Error, RuntimeError))
    
    def test_smtp_authentication_failure(self, warmup_campaigns):
        """Test handling of SMTP authentication failures during campaigns"""
        from monitoring.campaigns.warmup_campaigns import WarmupMailbox
        
        # Mock mailbox with invalid credentials
        invalid_mailbox = WarmupMailbox(
            email="invalid@test.com",
            password="wrong_password",
            smtp_host="smtp.test.com",
            smtp_port=587,
            imap_host="imap.test.com", 
            imap_port=993,
            provider="test"
        )
        
        # Test campaign execution with authentication failure
        with patch.object(warmup_campaigns, '_send_campaign_message', new_callable=AsyncMock) as mock_send:
            mock_send.side_effect = Exception("SMTP authentication failed")
            
            # Campaign should handle SMTP errors gracefully
            try:
                campaign_id = await warmup_campaigns.create_campaign("Newsletter", 5)
                await warmup_campaigns.execute_campaign(campaign_id)
                
                # Should complete without crashing, even with errors
                assert isinstance(campaign_id, int)
                
            except Exception as e:
                # Any exception should be logged and handled appropriately
                assert isinstance(e, (RuntimeError, ConnectionError))
    
    def test_email_delivery_failure_recovery(self, warmup_campaigns):
        """Test recovery from email delivery failures"""
        call_count = 0
        
        async def mock_send_with_failures(sender, recipient, subject, content, campaign_id):
            nonlocal call_count
            call_count += 1
            
            # Fail every 3rd email
            if call_count % 3 == 0:
                raise Exception("Email delivery failed")
            else:
                return f"message_id_{call_count}"
        
        with patch.object(warmup_campaigns, '_send_campaign_message', side_effect=mock_send_with_failures):
            campaign_id = await warmup_campaigns.create_campaign("Newsletter", 10)
            await warmup_campaigns.execute_campaign(campaign_id)
            
            # Campaign should complete despite some failures
            stats = warmup_campaigns.get_campaign_stats(campaign_id)
            
            assert stats['actual_interactions'] > 0
            assert stats['actual_interactions'] <= stats['target_interactions']
    
    def test_campaign_database_corruption_recovery(self, warmup_campaigns):
        """Test recovery from campaign database corruption"""
        with patch('sqlite3.connect') as mock_connect:
            # Simulate database corruption
            mock_conn = Mock()
            mock_cursor = Mock()
            mock_cursor.execute.side_effect = sqlite3.DatabaseError("Database disk image is malformed")
            mock_conn.cursor.return_value = mock_cursor
            mock_connect.return_value = mock_conn
            
            # Campaign operations should handle database errors
            with pytest.raises((sqlite3.DatabaseError, RuntimeError)):
                await warmup_campaigns.create_campaign("Test Campaign", 5)

class TestCascadingFailureScenarios:
    """Test handling of cascading failures across systems"""
    
    def test_dns_to_mailcow_failure_cascade(self):
        """Test failure cascade from DNS system to Mailcow operations"""
        try:
            from dns.managers.dns_manager import DNSManager
            from mailcow.core.api_client import MailcowAPI
        except ImportError:
            pytest.skip("Required modules not available")
        
        # Initialize both systems
        with patch.dict('os.environ', {'CLOUDFLARE_API_TOKEN': 'test_token'}):
            dns_manager = DNSManager()
        mailcow_api = MailcowAPI("mail.test.com", "test_key", verify_ssl=False)
        
        # Simulate DNS failure
        with patch.object(dns_manager, '_make_request', new_callable=AsyncMock) as mock_dns:
            mock_dns.side_effect = Exception("DNS API unavailable")
            
            # This should fail
            with pytest.raises(Exception):
                await dns_manager.create_dns_record("test.com", Mock())
            
            # But Mailcow should still work independently
            with patch.object(mailcow_api, '_request') as mock_mailcow:
                mock_mailcow.return_value = {"success": True}
                
                result = mailcow_api.get_domains()
                assert result["success"] is True
    
    def test_network_partition_handling(self):
        """Test behavior during network partitions"""
        try:
            from dns.managers.dns_manager import DNSManager
            from mailcow.core.api_client import MailcowAPI
            from monitoring.monitors.blacklist_monitor import BlacklistMonitor
        except ImportError:
            pytest.skip("Required modules not available")
        
        # Simulate network partition (all external requests fail)
        with patch('requests.Session.request') as mock_request:
            with patch('dns.resolver.Resolver.resolve') as mock_dns:
                mock_request.side_effect = ConnectionError("Network unreachable")
                mock_dns.side_effect = dns.resolver.Timeout("DNS unreachable")
                
                # All systems should handle network failures gracefully
                with patch.dict('os.environ', {'CLOUDFLARE_API_TOKEN': 'test_token'}):
                    dns_manager = DNSManager()
                mailcow_api = MailcowAPI("mail.test.com", "test_key")
                blacklist_monitor = BlacklistMonitor()
                
                # Operations should fail gracefully without crashing
                with pytest.raises((Exception, ConnectionError)):
                    await dns_manager.get_zones()
                
                assert mailcow_api.test_connection() is False
                
                result = await blacklist_monitor.check_ip_blacklists("192.168.1.100")
                assert isinstance(result, list)  # Should return empty list or error results
    
    def test_system_resource_exhaustion_cascade(self):
        """Test cascading effects of system resource exhaustion"""
        with patch('psutil.virtual_memory') as mock_memory:
            with patch('psutil.cpu_percent') as mock_cpu:
                # Simulate extreme resource exhaustion
                mock_memory.return_value = Mock(percent=98.0)  # 98% memory usage
                mock_cpu.return_value = 95.0  # 95% CPU usage
                
                try:
                    from vps.core.vps_manager import VPSManager
                    vps_manager = VPSManager()
                    
                    # System should still be able to report status
                    status = vps_manager.get_vps_status()
                    
                    assert 'system' in status
                    assert status['system']['memory_percent'] >= 98.0
                    assert status['system']['cpu_usage_percent'] >= 95.0
                    
                    # System should indicate critical resource usage
                    
                except ImportError:
                    pytest.skip("VPS manager not available")

class TestDataCorruptionScenarios:
    """Test handling of data corruption scenarios"""
    
    def test_config_file_corruption_recovery(self):
        """Test recovery from corrupted configuration files"""
        import tempfile
        import os
        
        try:
            from dns.managers.dns_manager import DNSManager
        except ImportError:
            pytest.skip("DNS manager not available")
        
        # Create corrupted config file
        with tempfile.NamedTemporaryFile(mode='w', suffix='.yaml', delete=False) as f:
            f.write("corrupted: yaml: content: [[[")
            corrupted_config_path = f.name
        
        try:
            # Should handle corrupted config gracefully
            with patch.dict('os.environ', {'CLOUDFLARE_API_TOKEN': 'test_token'}):
                dns_manager = DNSManager(corrupted_config_path)
                
                # Should fall back to defaults or environment variables
                assert dns_manager.api_token == 'test_token'
                
        except Exception as e:
            # Should raise appropriate configuration error
            assert 'config' in str(e).lower() or 'yaml' in str(e).lower()
        finally:
            os.unlink(corrupted_config_path)
    
    def test_database_schema_mismatch_handling(self):
        """Test handling of database schema mismatches"""
        try:
            from monitoring.monitors.blacklist_monitor import BlacklistMonitor
        except ImportError:
            pytest.skip("Blacklist monitor not available")
        
        with patch('sqlite3.connect') as mock_connect:
            mock_conn = Mock()
            mock_cursor = Mock()
            
            # Simulate schema mismatch error
            mock_cursor.execute.side_effect = sqlite3.OperationalError("no such column: new_column")
            mock_conn.cursor.return_value = mock_cursor
            mock_connect.return_value = mock_conn
            
            # Should handle schema mismatches gracefully
            with pytest.raises((sqlite3.OperationalError, RuntimeError)):
                blacklist_monitor = BlacklistMonitor()

if __name__ == "__main__":
    print("Running error scenario tests...")
    print("These tests validate error handling and system resilience")
    
    # Run with: pytest tests/error_scenarios/test_error_handling.py -v